Workbook

Sheet tblNhapDiem_0_0_67_18_1
A1: Stt | B1: Mã sinh viên | C1: Họ đệm | D1: Tên | E1: Ngày sinh | F1: Lớp | G1: Chọn | H1: Lần học | I1: Lần thi | J1: CC1*0.1+GK*0.3+THI1*0.6 - LTM.03.K15.01.LH.C04.1_LT | M1: TKHP | N1: Đánh giá | O1: Điểm chữ | P1: Điểm quy đổi | Q1: Xếp loại | R1: Tài khoản | S1: Thời gian
J2: CC1 | K2: GK | L2: THI1
A3: 1 | B3: 20211933 | C3: Doãn Hoàng | D3: Anh | E3: 19/10/2003 | F3: DCCNTT12.10.7 | H3: 2 | I3: 1 | J3: 10 | K3: =VLOOKUP(B3,Sheet1!$A:$E,5,0) -> 7
A4: 2 | B4: 24000107 | C4: Đỗ Hoàng | D4: Anh | E4: 09/09/2005 | F4: DCCNTT.15.1 | H4: 1 | I4: 1 | J4: 7 | K4: =VLOOKUP(B4,Sheet1!$A:$E,5,0) -> 0
A5: 3 | B5: 24000059 | C5: Lương Hoàng | D5: Anh | E5: 28/12/2006 | F5: DCCNTT.15.1 | H5: 1 | I5: 1 | J5: =VLOOKUP(B5,Sheet1!$A:$E,4,0) -> 8 | K5: =VLOOKUP(B5,Sheet1!$A:$E,5,0) -> 3
A6: 4 | B6: 24004325 | C6: Lương Hoàng | D6: Anh | E6: 14/02/2006 | F6: DCCNTT.15.1 | H6: 1 | I6: 1 | J6: =VLOOKUP(B6,Sheet1!$A:$E,4,0) -> 0 | K6: =VLOOKUP(B6,Sheet1!$A:$E,5,0) -> 0
A7: 5 | B7: 24000113 | C7: Nguyễn Viết | D7: Bằng | E7: 17/08/2006 | F7: DCCNTT.15.1 | H7: 1 | I7: 1 | J7: =VLOOKUP(B7,Sheet1!$A:$E,4,0) -> 8 | K7: =VLOOKUP(B7,Sheet1!$A:$E,5,0) -> 3
A8: 6 | B8: 24000465 | C8: Lê Đức | D8: Bình | E8: 25/04/2006 | F8: DCCNTT.15.1 | H8: 1 | I8: 1 | J8: 8 | K8: =VLOOKUP(B8,Sheet1!$A:$E,5,0) -> 6
A9: 7 | B9: 24000474 | C9: Nguyễn Thiện | D9: Chiến | E9: 27/09/2006 | F9: DCCNTT.15.1 | H9: 1 | I9: 1 | J9: 8 | K9: =VLOOKUP(B9,Sheet1!$A:$E,5,0) -> 5
A10: 8 | B10: 24000211 | C10: Đinh Công | D10: Chính | E10: 21/02/2006 | F10: DCCNTT.15.1 | H10: 1 | I10: 1 | J10: 7 | K10: =VLOOKUP(B10,Sheet1!$A:$E,5,0) -> 3
A11: 9 | B11: 24000104 | C11: Nguyễn Mạnh | D11: Cường | E11: 22/06/2006 | F11: DCCNTT.15.1 | H11: 1 | I11: 1 | J11: =VLOOKUP(B11,Sheet1!$A:$E,4,0) -> 8 | K11: =VLOOKUP(B11,Sheet1!$A:$E,5,0) -> 5
A12: 10 | B12: 24000279 | C12: Nguyễn Mạnh | D12: Cường | E12: 24/03/2006 | F12: DCCNTT.15.1 | H12: 1 | I12: 1 | J12: 7 | K12: =VLOOKUP(B12,Sheet1!$A:$E,5,0) -> 0
A13: 11 | B13: 24001341 | C13: Đinh Xuân | D13: Dũng | E13: 16/08/2006 | F13: DCCNTT.15.1 | H13: 1 | I13: 1 | J13: =VLOOKUP(B13,Sheet1!$A:$E,4,0) -> 0 | K13: =VLOOKUP(B13,Sheet1!$A:$E,5,0) -> 0
A14: 12 | B14: 24000123 | C14: Đào Tiến | D14: Dư | E14: 19/09/2006 | F14: DCCNTT.15.1 | H14: 1 | I14: 1 | J14: 9 | K14: =VLOOKUP(B14,Sheet1!$A:$E,5,0) -> 6
A15: 13 | B15: 20223839 | C15: Nguyễn Tùng | D15: Dương | E15: 19/11/2004 | F15: DCCNTT13.10.20 | H15: 2 | I15: 1 | J15: 6 | K15: =VLOOKUP(B15,Sheet1!$A:$E,5,0) -> 5
A16: 14 | B16: 24000669 | C16: Nguyễn Văn | D16: Dương | E16: 23/08/2006 | F16: DCCNTT.15.1 | H16: 1 | I16: 1 | J16: 7 | K16: =VLOOKUP(B16,Sheet1!$A:$E,5,0) -> 6
A17: 15 | B17: 24000320 | C17: Lưu Kim | D17: Đạt | E17: 04/11/2006 | F17: DCCNTT.15.1 | H17: 1 | I17: 1 | J17: 7 | K17: =VLOOKUP(B17,Sheet1!$A:$E,5,0) -> 0
A18: 16 | B18: 24000009 | C18: Đinh Công | D18: Đoàn | E18: 26/03/2003 | F18: DCCNTT.15.1 | H18: 1 | I18: 1 | J18: 7 | K18: =VLOOKUP(B18,Sheet1!$A:$E,5,0) -> 6
A19: 17 | B19: 24000462 | C19: Nguyễn Minh | D19: Đức | E19: 29/04/2006 | F19: DCCNTT.15.1 | H19: 1 | I19: 1 | J19: 8 | K19: =VLOOKUP(B19,Sheet1!$A:$E,5,0) -> 3
A20: 18 | B20: 20233164 | C20: Trần Văn | D20: Đức | E20: 13/10/2005 | F20: DCCNTT.14.8 | H20: 2 | I20: 1 | J20: =VLOOKUP(B20,Sheet1!$A:$E,4,0) -> 0 | K20: =VLOOKUP(B20,Sheet1!$A:$E,5,0) -> 0
A21: 19 | B21: 24000407 | C21: Nguyễn Trường | D21: Giang | E21: 09/01/2006 | F21: DCCNTT.15.1 | H21: 1 | I21: 1 | J21: 7 | K21: =VLOOKUP(B21,Sheet1!$A:$E,5,0) -> 5
A22: 20 | B22: 20213201 | C22: Trần Trường | D22: Giang | E22: 18/10/2003 | F22: DCCNTT12.10.11 | H22: 3 | I22: 1 | J22: 6 | K22: =VLOOKUP(B22,Sheet1!$A:$E,5,0) -> 3
A23: 21 | B23: 24000144 | C23: Nguyễn Minh | D23: Hiện | E23: 23/12/2006 | F23: DCCNTT.15.1 | H23: 1 | I23: 1 | J23: =VLOOKUP(B23,Sheet1!$A:$E,4,0) -> 0 | K23: =VLOOKUP(B23,Sheet1!$A:$E,5,0) -> 0
A24: 22 | B24: 24000392 | C24: Nguyễn Văn | D24: Hiệp | E24: 23/09/2006 | F24: DCCNTT.15.1 | H24: 1 | I24: 1 | J24: 7 | K24: =VLOOKUP(B24,Sheet1!$A:$E,5,0) -> 3
A25: 23 | B25: 24000275 | C25: Nguyễn Việt | D25: Hiếu | E25: 18/04/2006 | F25: DCCNTT.15.1 | H25: 1 | I25: 1 | J25: 7 | K25: =VLOOKUP(B25,Sheet1!$A:$E,5,0) -> 3
A26: 24 | B26: 24000299 | C26: Nguyễn Viết Trung | D26: Hiếu | E26: 22/10/2006 | F26: DCCNTT.15.1 | H26: 1 | I26: 1 | J26: 7 | K26: =VLOOKUP(B26,Sheet1!$A:$E,5,0) -> 6
A27: 25 | B27: 24000224 | C27: Phạm Trung | D27: Hiếu | E27: 09/05/2006 | F27: DCCNTT.15.1 | H27: 1 | I27: 1 | J27: 6 | K27: =VLOOKUP(B27,Sheet1!$A:$E,5,0) -> 6
A28: 26 | B28: 24000164 | C28: Phùng Quốc | D28: Hiếu | E28: 22/12/2006 | F28: DCCNTT.15.1 | H28: 1 | I28: 1 | J28: =VLOOKUP(B28,Sheet1!$A:$E,4,0) -> 0 | K28: =VLOOKUP(B28,Sheet1!$A:$E,5,0) -> 0
A29: 27 | B29: 24000078 | C29: Trương Minh | D29: Hiếu | E29: 29/12/2005 | F29: DCCNTT.15.1 | H29: 1 | I29: 1 | J29: =VLOOKUP(B29,Sheet1!$A:$E,4,0) -> 5 | K29: =VLOOKUP(B29,Sheet1!$A:$E,5,0) -> 4
A30: 28 | B30: 24001517 | C30: Nguyễn Thái | D30: Hoàng | E30: 21/11/2001 | F30: DCCNTT.15.1 | H30: 1 | I30: 1 | J30: 7 | K30: =VLOOKUP(B30,Sheet1!$A:$E,5,0) -> 4
A31: 29 | B31: 24000359 | C31: Trần Huy | D31: Hoàng | E31: 30/04/2006 | F31: DCCNTT.15.1 | H31: 1 | I31: 1 | J31: 6 | K31: =VLOOKUP(B31,Sheet1!$A:$E,5,0) -> 0
A32: 30 | B32: 24000091 | C32: Nguyễn Tiến | D32: Hùng | E32: 26/10/2006 | F32: DCCNTT.15.1 | H32: 1 | I32: 1 | J32: 7 | K32: =VLOOKUP(B32,Sheet1!$A:$E,5,0) -> 4
A33: 31 | B33: 24000264 | C33: Lê Mạnh | D33: Huy | E33: 07/11/2006 | F33: DCCNTT.15.1 | H33: 1 | I33: 1 | J33: 8 | K33: =VLOOKUP(B33,Sheet1!$A:$E,5,0) -> 4
A34: 32 | B34: 20213738 | C34: Nguyễn Bá | D34: Huy | E34: 21/02/2003 | F34: DCCNTT12.10.13 | H34: 3 | I34: 1 | J34: 6 | K34: =VLOOKUP(B34,Sheet1!$A:$E,5,0) -> 3
A35: 33 | B35: 24000340 | C35: Nguyễn Xuân | D35: Huy | E35: 25/08/2006 | F35: DCCNTT.15.1 | H35: 1 | I35: 1 | J35: =VLOOKUP(B35,Sheet1!$A:$E,4,0) -> 8 | K35: =VLOOKUP(B35,Sheet1!$A:$E,5,0) -> 3
A36: 34 | B36: 24000126 | C36: Trần Quang | D36: Huy | E36: 01/03/2006 | F36: DCCNTT.15.1 | H36: 1 | I36: 1 | J36: 7 | K36: =VLOOKUP(B36,Sheet1!$A:$E,5,0) -> 8
A37: 35 | B37: 24000184 | C37: Trịnh Xuân | D37: Huy | E37: 06/12/2006 | F37: DCCNTT.15.1 | H37: 1 | I37: 1 | J37: 8 | K37: =VLOOKUP(B37,Sheet1!$A:$E,5,0) -> 3
A38: 36 | B38: 24004311 | C38: Nguyễn Trần Việt | D38: Hưng | E38: 29/08/2006 | F38: DCCNTT.15.1 | H38: 1 | I38: 1 | J38: =VLOOKUP(B38,Sheet1!$A:$E,4,0) -> 0 | K38: =VLOOKUP(B38,Sheet1!$A:$E,5,0) -> 0
A39: 37 | B39: 24000261 | C39: Vũ Đình | D39: Hưng | E39: 28/05/2006 | F39: DCCNTT.15.1 | H39: 1 | I39: 1 | J39: 7 | K39: =VLOOKUP(B39,Sheet1!$A:$E,5,0) -> 6
A40: 38 | B40: 24000390 | C40: Hoàng Trung | D40: Kiên | E40: 18/09/2006 | F40: DCCNTT.15.1 | H40: 1 | I40: 1 | J40: 5 | K40: =VLOOKUP(B40,Sheet1!$A:$E,5,0) -> 3
...

Sheet Sheet1
A1: 24000107 | B1: Đỗ Hoàng | C1: Anh | D1: 6.86 | E1: 0
A2: 24004325 | B2: Lương Hoàng | C2: Anh | D2: 0 | E2: 0
A3: 24000279 | B3: Nguyễn Mạnh | C3: Cường | D3: 6.29 | E3: 0
A4: 24001341 | B4: Đinh Xuân | C4: Dũng | D4: 0 | E4: 0
A5: 24000320 | B5: Lưu Kim | C5: Đạt | D5: 6.86 | E5: 0
A6: 20233164 | B6: Trần Văn | C6: Đức | D6: 0 | E6: 0
A7: 24000144 | B7: Nguyễn Minh | C7: Hiện | D7: 0 | E7: 0
A8: 24000164 | B8: Phùng Quốc | C8: Hiếu | D8: 0 | E8: 0
A9: 24000359 | B9: Trần Huy | C9: Hoàng | D9: 5.72 | E9: 0
A10: 24004311 | B10: Nguyễn Trần Việt | C10: Hưng | D10: 0 | E10: 0
A11: 20223179 | B11: Quách Văn | C11: Lực | D11: 0 | E11: 0
A12: 24000085 | B12: Nguyễn Công | C12: Minh | D12: 0 | E12: 0
... A66: 24000422 | B66: Hà Xuân | C66: Triệu | D66: 10 | E66: 9
